<sdf version='1.9'>
  <model name='my_robot'>
    <link name='base_footprint'>
      <inertial>
        <pose>0.03778688524590164 0 0.1975409836065574 0 0 0</pose>
        <mass>6.0999999999999996</mass>
        <inertia>
          <ixx>0.1027839480874317</ixx>
          <ixy>0</ixy>
          <ixz>0.002433196721311467</ixz>
          <iyy>0.22662740437158471</iyy>
          <iyz>0</iyz>
          <izz>0.25867678961748641</izz>
        </inertia>
      </inertial>
      <collision name='base_footprint_fixed_joint_lump__base_link_collision'>
        <pose>0 0 0.2 0 0 0</pose>
        <geometry>
          <box>
            <size>0.6 0.4 0.2</size>
          </box>
        </geometry>
      </collision>
      <collision name='base_footprint_fixed_joint_lump__arm_base_link_collision_1'>
        <pose>0.2 0 0.3200000000000001 0 0 0</pose>
        <geometry>
          <box>
            <size>0.1 0.1 0.02</size>
          </box>
        </geometry>
      </collision>
      <collision name='base_footprint_fixed_joint_lump__camera_link_collision_2'>
        <pose>0.305 0 0.2 0 0 0</pose>
        <geometry>
          <box>
            <size>0.01 0.1 0.05</size>
          </box>
        </geometry>
        <surface>
          <contact>
            <ode/>
          </contact>
          <friction>
            <ode/>
          </friction>
        </surface>
      </collision>
      <collision name='base_footprint_fixed_joint_lump__sphere_collision_3'>
        <pose>0.2 0 0.05 0 0 0</pose>
        <geometry>
          <sphere>
            <radius>0.050000000000000003</radius>
          </sphere>
        </geometry>
        <surface>
          <contact>
            <ode/>
          </contact>
          <friction>
            <ode>
              <mu>0.10000000000000001</mu>
              <mu2>0.10000000000000001</mu2>
            </ode>
          </friction>
        </surface>
      </collision>
      <visual name='base_footprint_fixed_joint_lump__base_link_visual'>
        <pose>0 0 0.2 0 0 0</pose>
        <geometry>
          <box>
            <size>0.6 0.4 0.2</size>
          </box>
        </geometry>
        <material>
          <diffuse>0 0 0.625 1</diffuse>
          <ambient>0 0 0.625 1</ambient>
        </material>
      </visual>
      <visual name='base_footprint_fixed_joint_lump__arm_base_link_visual_1'>
        <pose>0.2 0 0.3200000000000001 0 0 0</pose>
        <geometry>
          <box>
            <size>0.1 0.1 0.02</size>
          </box>
        </geometry>
        <material>
          <diffuse>1 0.80875 0 1</diffuse>
          <ambient>1 0.80875 0 1</ambient>
        </material>
      </visual>
      <visual name='base_footprint_fixed_joint_lump__camera_link_visual_2'>
        <pose>0.305 0 0.2 0 0 0</pose>
        <geometry>
          <box>
            <size>0.01 0.1 0.05</size>
          </box>
        </geometry>
        <material>
          <diffuse>0.625 0.625 0.625 1</diffuse>
          <ambient>0.625 0.625 0.625 1</ambient>
        </material>
      </visual>
      <visual name='base_footprint_fixed_joint_lump__sphere_visual_3'>
        <pose>0.2 0 0.05 0 0 0</pose>
        <geometry>
          <sphere>
            <radius>0.050000000000000003</radius>
          </sphere>
        </geometry>
        <material>
          <diffuse>0.625 0.625 0.625 1</diffuse>
          <ambient>0.625 0.625 0.625 1</ambient>
        </material>
      </visual>
      <sensor name='camera' type='camera'>
        <camera>
          <image>
            <width>640</width>
            <height>480</height>
            <format>R8G8B8</format>
          </image>
          <clip>
            <near>0.10000000000000001</near>
            <far>15</far>
          </clip>
          <noise>
            <type>gaussian</type>
            <mean>0</mean>
            <stddev>0.0070000000000000001</stddev>
          </noise>
          <optical_frame_id>camera_link_optical</optical_frame_id>
          <camera_info_topic>camera/camera_info</camera_info_topic>
          <horisontal_fov>1.3962634</horisontal_fov>
          <horizontal_fov>1.0469999999999999</horizontal_fov>
        </camera>
        <always_on>true</always_on>
        <update_rate>20</update_rate>
        <visualize>true</visualize>
        <topic>camera/image_raw</topic>
        <pose>0.305 0 0.2 0 -0 0</pose>
      </sensor>
    </link>
    <joint name='arm_base_forearm_joint' type='revolute'>
      <pose relative_to='base_footprint'>0.2 0 0.33 0 0 0</pose>
      <parent>base_footprint</parent>
      <child>forearm_link</child>
      <axis>
        <xyz>0 1 0</xyz>
        <limit>
          <lower>0</lower>
          <upper>1.570796326794897</upper>
          <effort>100</effort>
          <velocity>100</velocity>
        </limit>
        <dynamics>
          <spring_reference>0</spring_reference>
          <spring_stiffness>0</spring_stiffness>
        </dynamics>
      </axis>
    </joint>
    <link name='forearm_link'>
      <pose relative_to='arm_base_forearm_joint'>0 0 0 0 0 0</pose>
      <inertial>
        <pose>0 0 0.15 0 0 0</pose>
        <mass>0.29999999999999999</mass>
        <inertia>
          <ixx>0.0022799999999999999</ixx>
          <ixy>0</ixy>
          <ixz>0</ixz>
          <iyy>0.0022799999999999999</iyy>
          <iyz>0</iyz>
          <izz>6.0000000000000002e-05</izz>
        </inertia>
      </inertial>
      <collision name='forearm_link_collision'>
        <pose>0 0 0.15 0 0 0</pose>
        <geometry>
          <cylinder>
            <length>0.29999999999999999</length>
            <radius>0.02</radius>
          </cylinder>
        </geometry>
      </collision>
      <visual name='forearm_link_visual'>
        <pose>0 0 0.15 0 0 0</pose>
        <geometry>
          <cylinder>
            <length>0.29999999999999999</length>
            <radius>0.02</radius>
          </cylinder>
        </geometry>
        <material>
          <diffuse>1 1 0 1</diffuse>
          <ambient>1 1 0 1</ambient>
        </material>
      </visual>
    </link>
    <joint name='forearm_hand_joint' type='revolute'>
      <pose relative_to='forearm_link'>0 0 0.3 0 0 0</pose>
      <parent>forearm_link</parent>
      <child>hand_link</child>
      <axis>
        <xyz>0 1 0</xyz>
        <limit>
          <lower>0</lower>
          <upper>1.570796326794897</upper>
          <effort>100</effort>
          <velocity>100</velocity>
        </limit>
        <dynamics>
          <spring_reference>0</spring_reference>
          <spring_stiffness>0</spring_stiffness>
        </dynamics>
      </axis>
    </joint>
    <link name='hand_link'>
      <pose relative_to='forearm_hand_joint'>0 0 0 0 0 0</pose>
      <inertial>
        <pose>0 0 0.15 0 0 0</pose>
        <mass>0.29999999999999999</mass>
        <inertia>
          <ixx>0.0022799999999999999</ixx>
          <ixy>0</ixy>
          <ixz>0</ixz>
          <iyy>0.0022799999999999999</iyy>
          <iyz>0</iyz>
          <izz>6.0000000000000002e-05</izz>
        </inertia>
      </inertial>
      <collision name='hand_link_collision'>
        <pose>0 0 0.15 0 0 0</pose>
        <geometry>
          <cylinder>
            <length>0.29999999999999999</length>
            <radius>0.02</radius>
          </cylinder>
        </geometry>
      </collision>
      <visual name='hand_link_visual'>
        <pose>0 0 0.15 0 0 0</pose>
        <geometry>
          <cylinder>
            <length>0.29999999999999999</length>
            <radius>0.02</radius>
          </cylinder>
        </geometry>
        <material>
          <diffuse>1 0.80875 0 1</diffuse>
          <ambient>1 0.80875 0 1</ambient>
        </material>
      </visual>
    </link>
    <joint name='base_left_wheel' type='revolute'>
      <pose relative_to='base_footprint'>-0.15 -0.225 0.1 0 0 0</pose>
      <parent>base_footprint</parent>
      <child>left_wheel</child>
      <axis>
        <xyz>0 1 0</xyz>
        <limit>
          <lower>-10000000000000000</lower>
          <upper>10000000000000000</upper>
        </limit>
        <dynamics>
          <spring_reference>0</spring_reference>
          <spring_stiffness>0</spring_stiffness>
        </dynamics>
      </axis>
    </joint>
    <link name='left_wheel'>
      <pose relative_to='base_left_wheel'>0 0 0 0 0 0</pose>
      <inertial>
        <pose>0 0 0 1.570796326794896 0 0</pose>
        <mass>1</mass>
        <inertia>
          <ixx>0.0027083333333333339</ixx>
          <ixy>0</ixy>
          <ixz>0</ixz>
          <iyy>0.0027083333333333339</iyy>
          <iyz>0</iyz>
          <izz>0.005000000000000001</izz>
        </inertia>
      </inertial>
      <collision name='left_wheel_collision'>
        <pose>0 0 0 0 0 0</pose>
        <geometry>
          <sphere>
            <radius>0.10000000000000001</radius>
          </sphere>
        </geometry>
      </collision>
      <visual name='left_wheel_visual'>
        <pose>0 0 0 1.570796326794896 0 0</pose>
        <geometry>
          <cylinder>
            <length>0.050000000000000003</length>
            <radius>0.10000000000000001</radius>
          </cylinder>
        </geometry>
        <material>
          <diffuse>0.625 0.625 0.625 1</diffuse>
          <ambient>0.625 0.625 0.625 1</ambient>
        </material>
      </visual>
    </link>
    <joint name='base_right_wheel' type='revolute'>
      <pose relative_to='base_footprint'>-0.15 0.225 0.1 0 0 0</pose>
      <parent>base_footprint</parent>
      <child>right_wheel</child>
      <axis>
        <xyz>0 1 0</xyz>
        <limit>
          <lower>-10000000000000000</lower>
          <upper>10000000000000000</upper>
        </limit>
        <dynamics>
          <spring_reference>0</spring_reference>
          <spring_stiffness>0</spring_stiffness>
        </dynamics>
      </axis>
    </joint>
    <link name='right_wheel'>
      <pose relative_to='base_right_wheel'>0 0 0 0 0 0</pose>
      <inertial>
        <pose>0 0 0 1.570796326794896 0 0</pose>
        <mass>1</mass>
        <inertia>
          <ixx>0.0027083333333333339</ixx>
          <ixy>0</ixy>
          <ixz>0</ixz>
          <iyy>0.0027083333333333339</iyy>
          <iyz>0</iyz>
          <izz>0.005000000000000001</izz>
        </inertia>
      </inertial>
      <collision name='right_wheel_collision'>
        <pose>0 0 0 0 0 0</pose>
        <geometry>
          <sphere>
            <radius>0.10000000000000001</radius>
          </sphere>
        </geometry>
      </collision>
      <visual name='right_wheel_visual'>
        <pose>0 0 0 1.570796326794896 0 0</pose>
        <geometry>
          <cylinder>
            <length>0.050000000000000003</length>
            <radius>0.10000000000000001</radius>
          </cylinder>
        </geometry>
        <material>
          <diffuse>0.625 0.625 0.625 1</diffuse>
          <ambient>0.625 0.625 0.625 1</ambient>
        </material>
      </visual>
    </link>
    <plugin name='gz::sim::systems::DiffDrive' filename='gz-sim-diff-drive-system'>
      <left_joint>base_left_wheel</left_joint>
      <right_joint>base_right_wheel</right_joint>
      <wheel_separation>0.45</wheel_separation>
      <wheel_radius>0.1</wheel_radius>
      <frame_id>odom</frame_id>
      <child_frame_id>base_footprint</child_frame_id>
    </plugin>
    <plugin name='gz::sim::systems::JointStatePublisher' filename='gz-sim-joint-state-publisher-system'>
      <joint_name>base_left_wheel</joint_name>
      <joint_name>base_right_wheel</joint_name>
    </plugin>
    <plugin name='gz::sim::systems::JointPositionController' filename='gz-sim-joint-position-controller-system'>
      <joint_name>arm_base_forearm_joint</joint_name>
      <topic>/model/my_robot/joint/arm_base_forearm_joint/cmd_pos</topic>
      <p_gain>20.0</p_gain>
      <d_gain>0.5</d_gain>
    </plugin>
    <plugin name='gz::sim::systems::JointPositionController' filename='gz-sim-joint-position-controller-system'>
      <joint_name>forearm_hand_joint</joint_name>
      <topic>/model/my_robot/joint/forearm_hand_joint/cmd_pos</topic>
      <p_gain>15.0</p_gain>
      <d_gain>0.5</d_gain>
    </plugin>
    <plugin name='gz::sim::systems::JointStatePublisher' filename='gz-sim-joint-state-publisher-system'>
      <joint_name>arm_base_forearm_joint</joint_name>
      <joint_name>forearm_hand_joint</joint_name>
    </plugin>
    <frame name='base_arm_base_joint' attached_to='base_link'>
      <pose>0.2 0 0.21 0 -0 0</pose>
    </frame>
    <frame name='arm_base_link' attached_to='base_arm_base_joint'/>
    <frame name='camera_optical_joint' attached_to='camera_link'>
      <pose>0 0 0 -1.5708 -0 -1.5708</pose>
    </frame>
    <frame name='camera_link_optical' attached_to='camera_optical_joint'/>
    <frame name='base_camera_joint' attached_to='base_link'>
      <pose>0.305 0 0.1 0 -0 0</pose>
    </frame>
    <frame name='camera_link' attached_to='base_camera_joint'/>
    <frame name='base_sphere' attached_to='base_link'>
      <pose>0.2 0 -0.05 0 -0 0</pose>
    </frame>
    <frame name='sphere' attached_to='base_sphere'/>
    <frame name='base_joint' attached_to='base_footprint'>
      <pose>0 0 0.1 0 -0 0</pose>
    </frame>
    <frame name='base_link' attached_to='base_joint'/>
  </model>
</sdf>
